#VRML_SIM R2025a utf8

EXTERNPROTO "https://raw.githubusercontent.com/cyberbotics/webots/R2025a/projects/objects/backgrounds/protos/TexturedBackground.proto"
EXTERNPROTO "https://raw.githubusercontent.com/cyberbotics/webots/R2025a/projects/objects/backgrounds/protos/TexturedBackgroundLight.proto"
EXTERNPROTO "https://raw.githubusercontent.com/cyberbotics/webots/R2025a/projects/objects/floors/protos/RectangleArena.proto"

WorldInfo {
}
Viewpoint {
  orientation -0.22581805510145364 0.24009314530654444 0.9441194244199232 1.5670141251158511
  position -0.002735315219130844 -0.6288981111353029 0.3465005652118949
}
TexturedBackground {
}
TexturedBackgroundLight {
}
RectangleArena {
}
Robot {
  translation -2.401862068269863e-18 -3.547763874817423e-18 0.009734970296622722
  rotation 0.6600941914537515 0.10647271931518798 0.7435988289734236 9.742906484525056e-17
  children [
    DEF Body Pose {
      translation 0 0 0.04
      children [
        Shape {
          appearance PBRAppearance {
            baseColor 0 0 1
            roughness 1
            metalness 0
          }
          geometry Cylinder {
            height 0.1
            radius 0.045
          }
        }
      ]
    }
    HingeJoint {
      jointParameters HingeJointParameters {
        anchor 0.045 0 0.012
      }
      device [
        DEF motor1 RotationalMotor {
          name "motor1"
        }
      ]
      endPoint Solid {
        translation 0.045 0 0.012
        rotation 0.0028862815722232337 -0.9999916676693721 -0.002886861706745229 4.707991889960249
        children [
          DEF wheel Shape {
            appearance PBRAppearance {
              baseColor 1 0 0
              roughness 1
              metalness 0
            }
            geometry Cylinder {
              height 0.01
              radius 0.025
            }
          }
        ]
        boundingObject USE wheel
        physics DEF wheel_physics Physics {
        }
      }
    }
    HingeJoint {
      jointParameters HingeJointParameters {
        position 1.3789521918566438e-17
        anchor -0.045 0 0.012
      }
      device [
        DEF motor2 RotationalMotor {
          name "motor2"
        }
      ]
      endPoint Solid {
        translation -0.045 0 0.012
        rotation 0.002876363080222929 -0.9999916672798734 -0.0028968787081596115 4.707991880458596
        children [
          USE wheel
        ]
        name "solid(1)"
        boundingObject USE wheel
        physics USE wheel_physics
      }
    }
  ]
  boundingObject USE Body
  physics Physics {
  }
  controller "drive_my_robot"
}
