#VRML_SIM R2025a utf8

EXTERNPROTO "https://raw.githubusercontent.com/cyberbotics/webots/R2025a/projects/objects/backgrounds/protos/TexturedBackground.proto"
EXTERNPROTO "https://raw.githubusercontent.com/cyberbotics/webots/R2025a/projects/objects/backgrounds/protos/TexturedBackgroundLight.proto"
EXTERNPROTO "https://raw.githubusercontent.com/cyberbotics/webots/R2025a/projects/objects/floors/protos/UnevenTerrain.proto"
EXTERNPROTO "https://raw.githubusercontent.com/cyberbotics/webots/R2025a/projects/appearances/protos/SandyGround.proto"

WorldInfo {
  info [
    "Mantis Hexapod Robot"
    "Author: Matt Denton"
  ]
  title "Mantis Hexapod"
  ERP 0.62
  basicTimeStep 10
  contactProperties [
    ContactProperties {
      coulombFriction [
        12
      ]
      softCFM 1e-05
    }
  ]
}
Viewpoint {
  orientation -0.27921459559051287 -0.4243702992958199 0.8613646490800528 4.8302987239619
  position -0.2548389180719802 0.22282580658717557 0.21161283436062603
  follow "Mantis"
}
TexturedBackground {
}
TexturedBackgroundLight {
}
UnevenTerrain {
  translation 0 0 -61.5
  rotation 0 0 1 -1.5708
  size 1000 1000 100
  xDimension 100
  yDimension 100
  appearance SandyGround {
    textureTransform TextureTransform {
      scale 1000 1000
    }
  }
  perlinNOctaves 8
}
Robot {
  children [
    HingeJoint {
      jointParameters HingeJointParameters {
        axis 0 0 1
        anchor -0.12 0 0.05
      }
      device [
        DEF nombre_joint PositionSensor {
          name "nombre_joint"
        }
        DEF nombre_joint_sensor RotationalMotor {
          name "nombre_joint_sensor"
        }
      ]
      endPoint DEF name_link Solid {
        children [
          HingeJoint {
            jointParameters HingeJointParameters {
              axis 0 1 0
              anchor -0.22 0 0.04
            }
            device [
              DEF second_jointB_sensor PositionSensor {
                name "second_jointB_sensor"
              }
              DEF secon_jointB RotationalMotor {
                name "second_jointB"
              }
            ]
          }
          Pose {
            translation -0.13 0 0.04
            rotation 0 0 1 3.141592653589793
            children [
              CadShape {
                url [
                  "../models/1A_link_collider.dae"
                ]
              }
            ]
          }
        ]
        name "name_link"
        boundingObject Pose {
          translation -0.13 0 0.04
          rotation 0 0 1 3.14159
          children [
            Mesh {
              url [
                "../models/1A_link_collider.dae"
              ]
            }
          ]
        }
      }
    }
    DEF base_link_visual Pose {
      children [
        CadShape {
          url [
            "../models/base_link_collider.dae"
          ]
        }
      ]
    }
  ]
  boundingObject Pose {
    children [
      Mesh {
        url [
          "../models/base_link_collider.dae"
        ]
      }
    ]
  }
  physics Physics {
    density -1
    mass 0.5
    centerOfMass [
      0 0 0
    ]
  }
}
